[2025-04-23 13:27:52,910] 1025 httpx - INFO - HTTP Request: GET https://dagshub.com/api/v1/user "HTTP/1.1 200 OK"
[2025-04-23 13:27:52,917] 107 dagshub - INFO - Accessing as Bharat34816
[2025-04-23 13:27:53,731] 1025 httpx - INFO - HTTP Request: GET https://dagshub.com/api/v1/repos/Bharat34816/networksecurity_mlops "HTTP/1.1 200 OK"
[2025-04-23 13:27:54,343] 1025 httpx - INFO - HTTP Request: GET https://dagshub.com/api/v1/user "HTTP/1.1 200 OK"
[2025-04-23 13:27:54,347] 107 dagshub - INFO - Initialized MLflow to track repo "Bharat34816/networksecurity_mlops"
[2025-04-23 13:27:54,349] 107 dagshub - INFO - Repository Bharat34816/networksecurity_mlops initialized!
[2025-04-23 13:28:54,545] 32 root - INFO - Start data Ingestion
[2025-04-23 13:29:07,372] 61 root - INFO - Performed train test split on the dataframe
[2025-04-23 13:29:07,373] 63 root - INFO - Exited split_data_as_train_test method of Data_Ingestion class
[2025-04-23 13:29:07,374] 71 root - INFO - Exporting train and test file path.
[2025-04-23 13:29:07,510] 80 root - INFO - Exported train and test file path.
[2025-04-23 13:29:07,511] 35 root - INFO - Data Ingestion completed and artifact: DataIngestionArtifact(trained_file_path='Artifacts\\data_ingestion\\ingested\\train.csv', test_file_path='Artifacts\\data_ingestion\\ingested\\test.csv')
[2025-04-23 13:29:07,533] 44 root - INFO - Initiate the data Validation
[2025-04-23 13:29:07,656] 34 root - INFO - Expected columns: 31, Actual columns: 31
[2025-04-23 13:29:07,656] 34 root - INFO - Expected columns: 31, Actual columns: 31
[2025-04-23 13:29:07,657] 13 root - ERROR - Error occured in python file [C:\Users\bhara\OneDrive\Desktop\MLops\networksecurity\components\data_validation.py] line number [41] error message ['list' object has no attribute 'keys'].
[2025-04-23 13:29:07,657] 13 root - ERROR - Error occured in python file [C:\Users\bhara\OneDrive\Desktop\MLops\networksecurity\components\data_validation.py] line number [96] error message [Error occured in python file [C:\Users\bhara\OneDrive\Desktop\MLops\networksecurity\components\data_validation.py] line number [41] error message ['list' object has no attribute 'keys'].].
[2025-04-23 13:29:07,657] 13 root - ERROR - Error occured in python file [C:\Users\bhara\OneDrive\Desktop\MLops\networksecurity\pipeline\training_pipeline.py] line number [45] error message [Error occured in python file [C:\Users\bhara\OneDrive\Desktop\MLops\networksecurity\components\data_validation.py] line number [96] error message [Error occured in python file [C:\Users\bhara\OneDrive\Desktop\MLops\networksecurity\components\data_validation.py] line number [41] error message ['list' object has no attribute 'keys'].].].
[2025-04-23 13:29:07,657] 13 root - ERROR - Error occured in python file [C:\Users\bhara\OneDrive\Desktop\MLops\networksecurity\pipeline\training_pipeline.py] line number [82] error message [Error occured in python file [C:\Users\bhara\OneDrive\Desktop\MLops\networksecurity\pipeline\training_pipeline.py] line number [45] error message [Error occured in python file [C:\Users\bhara\OneDrive\Desktop\MLops\networksecurity\components\data_validation.py] line number [96] error message [Error occured in python file [C:\Users\bhara\OneDrive\Desktop\MLops\networksecurity\components\data_validation.py] line number [41] error message ['list' object has no attribute 'keys'].].].].
[2025-04-23 13:29:07,657] 13 root - ERROR - Error occured in python file [C:\Users\bhara\OneDrive\Desktop\MLops\app.py] line number [58] error message [Error occured in python file [C:\Users\bhara\OneDrive\Desktop\MLops\networksecurity\pipeline\training_pipeline.py] line number [82] error message [Error occured in python file [C:\Users\bhara\OneDrive\Desktop\MLops\networksecurity\pipeline\training_pipeline.py] line number [45] error message [Error occured in python file [C:\Users\bhara\OneDrive\Desktop\MLops\networksecurity\components\data_validation.py] line number [96] error message [Error occured in python file [C:\Users\bhara\OneDrive\Desktop\MLops\networksecurity\components\data_validation.py] line number [41] error message ['list' object has no attribute 'keys'].].].].].
