[2025-04-23 12:51:13,877] 1025 httpx - INFO - HTTP Request: GET https://dagshub.com/api/v1/user "HTTP/1.1 200 OK"
[2025-04-23 12:51:13,890] 107 dagshub - INFO - Accessing as Bharat34816
[2025-04-23 12:51:14,424] 1025 httpx - INFO - HTTP Request: GET https://dagshub.com/api/v1/repos/Bharat34816/networksecurity_mlops "HTTP/1.1 200 OK"
[2025-04-23 12:51:15,057] 1025 httpx - INFO - HTTP Request: GET https://dagshub.com/api/v1/user "HTTP/1.1 200 OK"
[2025-04-23 12:51:15,076] 107 dagshub - INFO - Initialized MLflow to track repo "Bharat34816/networksecurity_mlops"
[2025-04-23 12:51:15,088] 107 dagshub - INFO - Repository Bharat34816/networksecurity_mlops initialized!
[2025-04-23 12:52:19,647] 32 root - INFO - Start data Ingestion
[2025-04-23 12:52:44,162] 61 root - INFO - Performed train test split on the dataframe
[2025-04-23 12:52:44,162] 63 root - INFO - Exited split_data_as_train_test method of Data_Ingestion class
[2025-04-23 12:52:44,163] 71 root - INFO - Exporting train and test file path.
[2025-04-23 12:52:44,481] 80 root - INFO - Exported train and test file path.
[2025-04-23 12:52:44,482] 35 root - INFO - Data Ingestion completed and artifact: DataIngestionArtifact(trained_file_path='Artifacts\\data_ingestion\\ingested\\train.csv', test_file_path='Artifacts\\data_ingestion\\ingested\\test.csv')
[2025-04-23 12:52:44,536] 44 root - INFO - Initiate the data Validation
[2025-04-23 12:52:44,759] 39 root - INFO - Required number of columns:2
[2025-04-23 12:52:44,759] 40 root - INFO - Data frame has columns:31
[2025-04-23 12:52:44,760] 39 root - INFO - Required number of columns:2
[2025-04-23 12:52:44,760] 40 root - INFO - Data frame has columns:31
[2025-04-23 12:52:44,791] 13 root - ERROR - Error occured in python file [C:\Users\bhara\OneDrive\Desktop\MLops\networksecurity\components\data_validation.py] line number [71] error message [local variable 'status' referenced before assignment].
[2025-04-23 12:52:44,791] 13 root - ERROR - Error occured in python file [C:\Users\bhara\OneDrive\Desktop\MLops\networksecurity\components\data_validation.py] line number [108] error message [Error occured in python file [C:\Users\bhara\OneDrive\Desktop\MLops\networksecurity\components\data_validation.py] line number [71] error message [local variable 'status' referenced before assignment].].
[2025-04-23 12:52:44,791] 13 root - ERROR - Error occured in python file [C:\Users\bhara\OneDrive\Desktop\MLops\networksecurity\pipeline\training_pipeline.py] line number [45] error message [Error occured in python file [C:\Users\bhara\OneDrive\Desktop\MLops\networksecurity\components\data_validation.py] line number [108] error message [Error occured in python file [C:\Users\bhara\OneDrive\Desktop\MLops\networksecurity\components\data_validation.py] line number [71] error message [local variable 'status' referenced before assignment].].].
[2025-04-23 12:52:44,792] 13 root - ERROR - Error occured in python file [C:\Users\bhara\OneDrive\Desktop\MLops\networksecurity\pipeline\training_pipeline.py] line number [82] error message [Error occured in python file [C:\Users\bhara\OneDrive\Desktop\MLops\networksecurity\pipeline\training_pipeline.py] line number [45] error message [Error occured in python file [C:\Users\bhara\OneDrive\Desktop\MLops\networksecurity\components\data_validation.py] line number [108] error message [Error occured in python file [C:\Users\bhara\OneDrive\Desktop\MLops\networksecurity\components\data_validation.py] line number [71] error message [local variable 'status' referenced before assignment].].].].
[2025-04-23 12:52:44,794] 13 root - ERROR - Error occured in python file [C:\Users\bhara\OneDrive\Desktop\MLops\app.py] line number [58] error message [Error occured in python file [C:\Users\bhara\OneDrive\Desktop\MLops\networksecurity\pipeline\training_pipeline.py] line number [82] error message [Error occured in python file [C:\Users\bhara\OneDrive\Desktop\MLops\networksecurity\pipeline\training_pipeline.py] line number [45] error message [Error occured in python file [C:\Users\bhara\OneDrive\Desktop\MLops\networksecurity\components\data_validation.py] line number [108] error message [Error occured in python file [C:\Users\bhara\OneDrive\Desktop\MLops\networksecurity\components\data_validation.py] line number [71] error message [local variable 'status' referenced before assignment].].].].].
