[2025-04-22 17:47:53,164] 16 root - INFO - Data ingestion initiated
[2025-04-22 17:50:01,562] 13 root - ERROR - Error occured in python file [C:\Users\bhara\OneDrive\Desktop\MLops\networksecurity\components\data_ingestion.py] line number [37] error message [ac-8klab8i-shard-00-01.b6qxiwq.mongodb.net:27017: connection closed (configured timeouts: connectTimeoutMS: 20000.0ms)].
[2025-04-22 17:50:01,564] 13 root - ERROR - Error occured in python file [C:\Users\bhara\OneDrive\Desktop\MLops\networksecurity\components\data_ingestion.py] line number [89] error message [Error occured in python file [C:\Users\bhara\OneDrive\Desktop\MLops\networksecurity\components\data_ingestion.py] line number [37] error message [ac-8klab8i-shard-00-01.b6qxiwq.mongodb.net:27017: connection closed (configured timeouts: connectTimeoutMS: 20000.0ms)].].
[2025-04-22 17:50:01,565] 13 root - ERROR - Error occured in python file [C:\Users\bhara\OneDrive\Desktop\MLops\main.py] line number [17] error message [Error occured in python file [C:\Users\bhara\OneDrive\Desktop\MLops\networksecurity\components\data_ingestion.py] line number [89] error message [Error occured in python file [C:\Users\bhara\OneDrive\Desktop\MLops\networksecurity\components\data_ingestion.py] line number [37] error message [ac-8klab8i-shard-00-01.b6qxiwq.mongodb.net:27017: connection closed (configured timeouts: connectTimeoutMS: 20000.0ms)].].].
